<?xml version="1.0" encoding="UTF-8"?>
<robot xmlns:xacro="http://www.ros.org/wiki/xacro" name="amr_robot">

  <!-- ============================= -->
  <!-- Define robot constants -->

  <!-- ============================= -->

  <!-- ============================= -->
  <!-- Define some commonly used inertial properties -->
 
  <!-- ============================= -->

  <!-- ============================= -->
  <!-- Robot Base -->
  <link name="base_link">
    <inertial>
      <origin xyz="0.264961530183372 0.00225996356394289 0.112161694553598" rpy="0 0 0"/>
      <mass value="28.3239204847698"/>
      <inertia ixx="0.136989288705436" ixy="-0.00013586267118142" ixz="0.000216303712387318"
               iyy="0.455306795955337" iyz="0.00115313054501806" izz="0.538335903712105"/>
    </inertial>
    <visual>
      <origin xyz="0 0 0" rpy="0 0 0"/>
      <geometry>
        <mesh filename="package://amr_description/meshes/base_link.STL"/>
      </geometry>
      <material name="">
        <color rgba="0.792156862745098 0.819607843137255 0.933333333333333 1"/>
      </material>
    </visual>
    <collision>
      <origin xyz="0 0 0" rpy="0 0 0"/>
      <geometry>
        <mesh filename="package://amr_description/meshes/base_link.STL"/>
      </geometry>
    </collision>
  </link>

  <!-- ============================= -->
  <!-- Robot Footprint: Wheels and Caster -->
  <!-- Left Wheel -->
  <link name="left_wheel">
    <inertial>
      <origin xyz="0 0 0" rpy="0 0 0"/>
      <mass value="0.94018"/>
      <inertia ixx="0.0030878" ixy="0" ixz="0"
               iyy="0.0030878" iyz="0" izz="0.0058343"/>
    </inertial>
    <visual>
      <origin xyz="0 0 0" rpy="0 0 0"/>
      <geometry>
        <mesh filename="package://amr_description/meshes/left_wheel.STL"/>
      </geometry>
      <material name="">
        <color rgba="0.79216 0.81961 0.93333 1"/>
      </material>
    </visual>
    <collision>
      <origin xyz="0 0 0" rpy="0 0 0"/>
      <geometry>
        <mesh filename="package://amr_description/meshes/left_wheel.STL"/>
      </geometry>
    </collision>
  </link>
  <joint name="left_wheel_joint" type="continuous">
    <origin xyz="-0.013203 0.24052 0.064" rpy="-1.5708 0 0"/>
    <parent link="base_link"/>
    <child link="left_wheel"/>
    <axis xyz="0 0 1"/>
    <limit effort="10" velocity="10"/>
    <dynamics damping="0.1" friction="0.01"/>
  </joint>

  <!-- Right Wheel -->
  <link name="right_wheel">
    <inertial>
      <origin xyz="0 0 0" rpy="0 0 0"/>
      <mass value="0.94018365156767"/>
      <inertia ixx="0.00308782611811812" ixy="0" ixz="0"
               iyy="0.00308782611811811" iyz="0" izz="0.00583434941184945"/>
    </inertial>
    <visual>
      <origin xyz="0 0 0" rpy="0 0 0"/>
      <geometry>
        <mesh filename="package://amr_description/meshes/right_wheel.STL"/>
      </geometry>
      <material name="">
        <color rgba="0.792156862745098 0.819607843137255 0.933333333333333 1"/>
      </material>
    </visual>
    <collision>
      <origin xyz="0 0 0" rpy="0 0 0"/>
      <geometry>
        <mesh filename="package://amr_description/meshes/right_wheel.STL"/>
      </geometry>
    </collision>
  </link>
  <joint name="right_wheel_joint" type="continuous">
    <origin xyz="-0.013203 -0.24048 0.064" rpy="-1.5708 0 0"/>
    <parent link="base_link"/>
    <child link="right_wheel"/>
    <axis xyz="0 0 -1"/>
    <limit effort="10" velocity="10"/>
    <dynamics damping="0.1" friction="0.01"/>
  </joint>

  <!-- Caster -->
  <link name="caster">
    <inertial>
      <origin xyz="0.0181380765705021 -0.00032074694194453 -0.0524126710459661" rpy="0 0 0"/>
      <mass value="0.112454546873097"/>
      <inertia ixx="8.80309430168958E-05" ixy="0" ixz="0"
               iyy="6.46284651214001E-05" iyz="0" izz="0.000111462019026295"/>
    </inertial>
    <visual>
      <origin xyz="0 0 0" rpy="0 0 0"/>
      <geometry>
        <mesh filename="package://amr_description/meshes/caster.STL"/>
      </geometry>
      <material name="">
        <color rgba="0.792156862745098 0.819607843137255 0.933333333333333 1"/>
      </material>
    </visual>
    <collision>
      <origin xyz="0 0 0" rpy="0 0 0"/>
      <geometry>
        <mesh filename="package://amr_description/meshes/caster.STL"/>
      </geometry>
    </collision>
  </link>
  <joint name="caster_joint" type="continuous">
    <origin xyz="0.5498 0 0.0765" rpy="0 0 0"/>
    <parent link="base_link"/>
    <child link="caster"/>
    <axis xyz="0 0 -1"/>
    <limit effort="10" velocity="10"/>
    <dynamics damping="0.01" friction="0.01"/>
  </joint>

  <!-- Caster Wheel -->
  <link name="caster_wheel">
    <inertial>
      <origin xyz="0 0 0" rpy="0 0 0"/>
      <mass value="0.15047968496888"/>
      <inertia ixx="6.68462901317433E-05" ixy="0" ixz="0"
               iyy="6.68462901317433E-05" iyz="0" izz="0.000122637940378903"/>
    </inertial>
    <visual>
      <origin xyz="0 0 0" rpy="0 0 0"/>
      <geometry>
        <mesh filename="package://amr_description/meshes/caster_wheel.STL"/>
      </geometry>
      <material name="">
        <color rgba="0.792156862745098 0.819607843137255 0.933333333333333 1"/>
      </material>
    </visual>
    <collision>
      <origin xyz="0 0 0" rpy="0 0 0"/>
      <geometry>
        <mesh filename="package://amr_description/meshes/caster_wheel.STL"/>
      </geometry>
    </collision>
  </link>
  <joint name="caster_wheel_joint" type="continuous">
    <origin xyz="-0.019972 -0.0032939 -0.075" rpy="-1.5708 0 0"/>
    <parent link="caster"/>
    <child link="caster_wheel"/>
    <axis xyz="0 0 -1"/>
    <limit effort="10" velocity="10"/>
    <dynamics damping="0.01" friction="0.01"/>
  </joint>

  <!-- ============================= -->
  <!-- IMU, Lidar, Camera -->
  <!-- Rear Lidar -->
  <link name="rear_lidar">
    <inertial>
      <origin xyz="0.00207355210295557 0  -0.0528498007205547" rpy="0 0 0"/>
      <mass value="0.208748884092951"/>
      <inertia ixx="0.00014021743447073" ixy="0" ixz="0"
               iyy="0.000137323574056695" iyz="0" izz="9.31238270300697E-05"/>
    </inertial>
    <visual>
      <origin xyz="0 0 0" rpy="0 0 0"/>
      <geometry>
        <mesh filename="package://amr_description/meshes/rear_lidar.STL"/>
      </geometry>
      <material name="">
        <color rgba="0.792156862745098 0.819607843137255 0.933333333333333 1"/>
      </material>
    </visual>
    <collision>
      <origin xyz="0 0 0" rpy="0 0 0"/>
      <geometry>
        <mesh filename="package://amr_description/meshes/rear_lidar.STL"/>
      </geometry>
    </collision>
  </link>
  <joint name="rear_lidar_joint" type="continuous">
    <origin xyz="-0.19691 -0.18272 0.13918" rpy="0 0 0"/>
    <parent link="base_link"/>
    <child link="rear_lidar"/>
    <axis xyz="0 0 1"/>
  </joint>

  <!-- Front Lidar -->
  <link name="front_lidar">
    <inertial>
      <origin xyz="0 0 0" rpy="0 0 0"/>
      <mass value="0.208748881672676"/>
      <inertia ixx="0.000140216872845025" ixy="0" ixz="0"
               iyy="0.00013732411854646" iyz="0" izz="9.31238252061991E-05"/>
    </inertial>
    <visual>
      <origin xyz="0 0 0" rpy="0 0 0"/>
      <geometry>
        <mesh filename="package://amr_description/meshes/front_lidar.STL"/>
      </geometry>
      <material name="">
        <color rgba="0.792156862745098 0.819607843137255 0.933333333333333 1"/>
      </material>
    </visual>
    <collision>
      <origin xyz="0 0 0" rpy="0 0 0"/>
      <geometry>
        <mesh filename="package://amr_description/meshes/front_lidar.STL"/>
      </geometry>
    </collision>
  </link>
  <joint name="front_lidar_joint" type="continuous">
    <origin xyz="0.7598 0.0027433 0.14323" rpy="0 0 0"/>
    <parent link="base_link"/>
    <child link="front_lidar"/>
    <axis xyz="0 0 -1"/>
  </joint>

</robot>
